/home/modelrep/sadiya/miniconda/envs/pytorch/lib/python3.9/site-packages/sklearn/linear_model/_logistic.py:460: ConvergenceWarning: lbfgs failed to converge (status=1):
STOP: TOTAL NO. of ITERATIONS REACHED LIMIT.

Increase the number of iterations (max_iter) or scale the data as shown in:
    https://scikit-learn.org/stable/modules/preprocessing.html
Please also refer to the documentation for alternative solver options:
    https://scikit-learn.org/stable/modules/linear_model.html#logistic-regression
  n_iter_i = _check_optimize_result(
/home/modelrep/sadiya/miniconda/envs/pytorch/lib/python3.9/site-packages/sklearn/linear_model/_logistic.py:460: ConvergenceWarning: lbfgs failed to converge (status=1):
STOP: TOTAL NO. of ITERATIONS REACHED LIMIT.

Increase the number of iterations (max_iter) or scale the data as shown in:
    https://scikit-learn.org/stable/modules/preprocessing.html
Please also refer to the documentation for alternative solver options:
    https://scikit-learn.org/stable/modules/linear_model.html#logistic-regression
  n_iter_i = _check_optimize_result(
/home/modelrep/sadiya/miniconda/envs/pytorch/lib/python3.9/site-packages/sklearn/linear_model/_logistic.py:460: ConvergenceWarning: lbfgs failed to converge (status=1):
STOP: TOTAL NO. of ITERATIONS REACHED LIMIT.

Increase the number of iterations (max_iter) or scale the data as shown in:
    https://scikit-learn.org/stable/modules/preprocessing.html
Please also refer to the documentation for alternative solver options:
    https://scikit-learn.org/stable/modules/linear_model.html#logistic-regression
  n_iter_i = _check_optimize_result(
Traceback (most recent call last):
  File "/home/modelrep/sadiya/tobias_ettling/ML_Models_BrainAge/LogisticRegression/shapValues.py", line 77, in <module>
    explainer = shap.KernelExplainer(best_model.predict, shap.sample(x_train_df, 10), num_jobs=-2)
  File "/home/modelrep/sadiya/miniconda/envs/pytorch/lib/python3.9/site-packages/shap/explainers/_kernel.py", line 96, in __init__
    model_null = match_model_to_data(self.model, self.data)
  File "/home/modelrep/sadiya/miniconda/envs/pytorch/lib/python3.9/site-packages/shap/utils/_legacy.py", line 123, in match_model_to_data
    out_val = model.f(data.data)
  File "/home/modelrep/sadiya/miniconda/envs/pytorch/lib/python3.9/site-packages/sklearn/linear_model/_base.py", line 451, in predict
    scores = self.decision_function(X)
  File "/home/modelrep/sadiya/miniconda/envs/pytorch/lib/python3.9/site-packages/sklearn/linear_model/_base.py", line 429, in decision_function
    check_is_fitted(self)
  File "/home/modelrep/sadiya/miniconda/envs/pytorch/lib/python3.9/site-packages/sklearn/utils/validation.py", line 1462, in check_is_fitted
    raise NotFittedError(msg % {"name": type(estimator).__name__})
sklearn.exceptions.NotFittedError: This LogisticRegression instance is not fitted yet. Call 'fit' with appropriate arguments before using this estimator.
